{
 "cells": [
  {
   "cell_type": "markdown",
   "id": "958b30af-b301-48d7-84b2-d505d0b20540",
   "metadata": {},
   "source": [
    "# Q1. What is an Exception in pthon? Write the difference between Exceptions and syntax error."
   ]
  },
  {
   "cell_type": "markdown",
   "id": "b3fe66c8-7777-4f67-becd-bdb31458d4f5",
   "metadata": {},
   "source": [
    "In Python, an exception is an error that occurs during the execution of a program. When an exception occurs, the program execution is disrupted and Python generates an exception object to describe the error.\n",
    "\n",
    "Exceptions can occur due to various reasons, such as invalid user input, resource unavailability, memory errors, and so on. By handling exceptions, a program can gracefully recover from errors and continue its execution, instead of crashing or producing incorrect results.\n",
    "The key differences between exceptions and syntax errors are:\n",
    "\n",
    "1. Exceptions occur during the execution of a program, while syntax errors occur during the parsing of the code before it is executed.\n",
    "2. Exceptions are generated by Python when an error occurs, while syntax errors are detected by the Python interpreter before the program starts running.\n",
    "3. Exceptions can be handled by the program using try-except blocks, while syntax errors must be fixed manually by correcting the code.\n",
    "4. Exceptions can occur at runtime and can be due to a variety of reasons, while syntax errors are typically due to mistakes in the code and can be detected by the Python interpreter."
   ]
  },
  {
   "cell_type": "markdown",
   "id": "f0966e16-ed4d-4b4e-b2c1-476c8842316a",
   "metadata": {},
   "source": [
    "# Q2. What hppens when an exception is not hndled? Explin with an exmple."
   ]
  },
  {
   "cell_type": "markdown",
   "id": "422666da-1bdb-4e79-ab1d-6c5eeb14ebf4",
   "metadata": {},
   "source": [
    "If an exception is not handled in Python, it will cause the program to terminate abruptly and an error message will be displayed. This can result in unexpected behavior and data loss, and is generally not desirable.\n"
   ]
  },
  {
   "cell_type": "code",
   "execution_count": 1,
   "id": "7fc549c3-6a0d-40cf-85a7-b19540c2b811",
   "metadata": {},
   "outputs": [
    {
     "ename": "ZeroDivisionError",
     "evalue": "division by zero",
     "output_type": "error",
     "traceback": [
      "\u001b[0;31m---------------------------------------------------------------------------\u001b[0m",
      "\u001b[0;31mZeroDivisionError\u001b[0m                         Traceback (most recent call last)",
      "Cell \u001b[0;32mIn[1], line 7\u001b[0m\n\u001b[1;32m      4\u001b[0m     z \u001b[38;5;241m=\u001b[39m x \u001b[38;5;241m/\u001b[39m y\n\u001b[1;32m      5\u001b[0m     \u001b[38;5;28mprint\u001b[39m(z)\n\u001b[0;32m----> 7\u001b[0m \u001b[43mdivide_by_zero\u001b[49m\u001b[43m(\u001b[49m\u001b[43m)\u001b[49m\n",
      "Cell \u001b[0;32mIn[1], line 4\u001b[0m, in \u001b[0;36mdivide_by_zero\u001b[0;34m()\u001b[0m\n\u001b[1;32m      2\u001b[0m x \u001b[38;5;241m=\u001b[39m \u001b[38;5;241m10\u001b[39m\n\u001b[1;32m      3\u001b[0m y \u001b[38;5;241m=\u001b[39m \u001b[38;5;241m0\u001b[39m\n\u001b[0;32m----> 4\u001b[0m z \u001b[38;5;241m=\u001b[39m \u001b[43mx\u001b[49m\u001b[43m \u001b[49m\u001b[38;5;241;43m/\u001b[39;49m\u001b[43m \u001b[49m\u001b[43my\u001b[49m\n\u001b[1;32m      5\u001b[0m \u001b[38;5;28mprint\u001b[39m(z)\n",
      "\u001b[0;31mZeroDivisionError\u001b[0m: division by zero"
     ]
    }
   ],
   "source": [
    "def divide_by_zero():\n",
    "    x = 10\n",
    "    y = 0\n",
    "    z = x / y\n",
    "    print(z)\n",
    "\n",
    "divide_by_zero()\n"
   ]
  },
  {
   "cell_type": "markdown",
   "id": "32d6ba96-9605-411d-b3b2-0ab9c2d7bf4b",
   "metadata": {},
   "source": [
    "# Q3. Which Python statements are used to catch and handle exceptions? Explain with an example."
   ]
  },
  {
   "cell_type": "markdown",
   "id": "d315f26a-b234-4daf-bc41-71c574cd2aea",
   "metadata": {},
   "source": [
    "In Python, the try and except statements are used to catch and handle exceptions. The try block contains the code that may raise an exception, and the except block contains the code that handles the exception if it occurs."
   ]
  },
  {
   "cell_type": "code",
   "execution_count": 2,
   "id": "8b82ff40-246c-4e7e-ade7-99c197d1c49e",
   "metadata": {},
   "outputs": [],
   "source": [
    "import logging\n",
    "logging.basicConfig(filename = 'error.txt' , level = logging.ERROR)\n",
    "\n",
    "try :\n",
    "    10/0\n",
    "    \n",
    "except ZeroDivisionError as e :\n",
    "    logging.error(\"i am tring to handle a zero division error {}\".format(e))"
   ]
  },
  {
   "cell_type": "markdown",
   "id": "67986388-bea8-44ad-8bb7-0a992b77e5f8",
   "metadata": {},
   "source": [
    "# Q4. Explain with an example:\n",
    "# a) try and else\n",
    "# b) finally\n",
    "# c) raise"
   ]
  },
  {
   "cell_type": "markdown",
   "id": "b6b4126d-0ade-4ed0-89ac-39d521b96267",
   "metadata": {},
   "source": [
    "# a) try and else\n",
    "In Python, the try and except statements are used to catch and handle exceptions. The try block contains the code that may raise an exception, and the except block contains the code that handles the exception if it occurs."
   ]
  },
  {
   "cell_type": "code",
   "execution_count": 5,
   "id": "010a1f5d-6c2b-44b1-86d7-2a3cc5792499",
   "metadata": {},
   "outputs": [],
   "source": [
    "import logging\n",
    "logging.basicConfig(filename = 'error.txt' , level = logging.ERROR)\n",
    "\n",
    "try :\n",
    "    10/0\n",
    "    \n",
    "except ZeroDivisionError as e :\n",
    "    logging.error(\"i am tring to handle a zero division error {}\".format(e))"
   ]
  },
  {
   "cell_type": "markdown",
   "id": "c6146167-93de-4b0f-aeec-3462fc085d80",
   "metadata": {},
   "source": [
    "# b) finally"
   ]
  },
  {
   "cell_type": "markdown",
   "id": "4a6f0c2d-ba76-4e13-8efa-b8fb53ec7755",
   "metadata": {},
   "source": [
    "In Python, the finally statement is used in conjunction with try and except blocks to define a block of code that will be executed regardless of whether an exception is raised or not. The code inside the finally block will always be executed, even if an exception occurs and is caught by an except block or if the try block completes without any exception being raised."
   ]
  },
  {
   "cell_type": "code",
   "execution_count": 6,
   "id": "6e81ab12-d6cc-4808-a6bf-c9f3301ad362",
   "metadata": {},
   "outputs": [],
   "source": [
    "try:\n",
    "    with open(\"test.txt\" ,'r') as f :\n",
    "        f.write(\"this is my data to file\")\n",
    "except FileNotFoundError as e :\n",
    "    logging.error('i am handling file not found {}'.format(e))\n",
    "finally :\n",
    "    f.close()"
   ]
  },
  {
   "cell_type": "markdown",
   "id": "8e6582a3-3470-4558-ab81-52f4452bf2a9",
   "metadata": {},
   "source": [
    "# c) raise"
   ]
  },
  {
   "cell_type": "markdown",
   "id": "e38d8f63-e845-475b-a54b-690ce5299a5f",
   "metadata": {},
   "source": [
    "In Python, the raise statement is used to manually raise an exception. This is useful when you want to explicitly signal that an error has occurred in your code and terminate execution of the program or function."
   ]
  },
  {
   "cell_type": "code",
   "execution_count": 7,
   "id": "d4474906-d8d6-4f97-b01e-6cce123a5dad",
   "metadata": {},
   "outputs": [
    {
     "name": "stdout",
     "output_type": "stream",
     "text": [
      "5.0\n"
     ]
    },
    {
     "ename": "ZeroDivisionError",
     "evalue": "division by zero",
     "output_type": "error",
     "traceback": [
      "\u001b[0;31m---------------------------------------------------------------------------\u001b[0m",
      "\u001b[0;31mZeroDivisionError\u001b[0m                         Traceback (most recent call last)",
      "Cell \u001b[0;32mIn[7], line 9\u001b[0m\n\u001b[1;32m      6\u001b[0m result \u001b[38;5;241m=\u001b[39m divide(\u001b[38;5;241m10\u001b[39m, \u001b[38;5;241m2\u001b[39m)\n\u001b[1;32m      7\u001b[0m \u001b[38;5;28mprint\u001b[39m(result)\n\u001b[0;32m----> 9\u001b[0m result \u001b[38;5;241m=\u001b[39m \u001b[43mdivide\u001b[49m\u001b[43m(\u001b[49m\u001b[38;5;241;43m10\u001b[39;49m\u001b[43m,\u001b[49m\u001b[43m \u001b[49m\u001b[38;5;241;43m0\u001b[39;49m\u001b[43m)\u001b[49m\n",
      "Cell \u001b[0;32mIn[7], line 3\u001b[0m, in \u001b[0;36mdivide\u001b[0;34m(x, y)\u001b[0m\n\u001b[1;32m      1\u001b[0m \u001b[38;5;28;01mdef\u001b[39;00m \u001b[38;5;21mdivide\u001b[39m(x, y):\n\u001b[1;32m      2\u001b[0m     \u001b[38;5;28;01mif\u001b[39;00m y \u001b[38;5;241m==\u001b[39m \u001b[38;5;241m0\u001b[39m:\n\u001b[0;32m----> 3\u001b[0m         \u001b[38;5;28;01mraise\u001b[39;00m \u001b[38;5;167;01mZeroDivisionError\u001b[39;00m(\u001b[38;5;124m\"\u001b[39m\u001b[38;5;124mdivision by zero\u001b[39m\u001b[38;5;124m\"\u001b[39m)\n\u001b[1;32m      4\u001b[0m     \u001b[38;5;28;01mreturn\u001b[39;00m x \u001b[38;5;241m/\u001b[39m y\n",
      "\u001b[0;31mZeroDivisionError\u001b[0m: division by zero"
     ]
    }
   ],
   "source": [
    "def divide(x, y):\n",
    "    if y == 0:\n",
    "        raise ZeroDivisionError(\"division by zero\")\n",
    "    return x / y\n",
    "\n",
    "result = divide(10, 2)\n",
    "print(result)\n",
    "\n",
    "result = divide(10, 0)\n"
   ]
  },
  {
   "cell_type": "markdown",
   "id": "89c04b59-58a5-43d9-a4aa-70c93b23b7c6",
   "metadata": {},
   "source": [
    "# Q5. What are Custom Exceptions in python? Why do we need Custom Exceptions? Explain with an example."
   ]
  },
  {
   "cell_type": "markdown",
   "id": "db37f862-365d-4146-a2b1-95c241c2ec65",
   "metadata": {},
   "source": [
    "In Python, we can define our own custom exceptions by creating a new class that inherits from the built-in Exception class or one of its subclasses. Custom exceptions can be used to provide more specific error handling for a particular program or library, and can make it easier to identify and fix issues in the code.\n",
    "\n",
    "We may need custom exceptions because the built-in exceptions may not always be specific enough for our use case. For example, if we are building a financial application and need to handle errors related to insufficient funds, we could create a custom InsufficientFundsError exception that provides a more specific error message and context for the user."
   ]
  },
  {
   "cell_type": "code",
   "execution_count": 12,
   "id": "03e8fbe3-7e3b-4b64-bf26-fd217fc4df05",
   "metadata": {},
   "outputs": [],
   "source": [
    "import logging\n",
    "logging.basicConfig(filename = 'error.txt' , level = logging.DEBUG)\n",
    "\n",
    "class InsufficientFundsError(Exception):\n",
    "    def __init__(self, balance, amount):\n",
    "        self.balance = balance\n",
    "        self.amount = amount\n",
    "\n",
    "    def __str__(self):\n",
    "        return f\"Insufficient funds: balance is {self.balance}, but tried to withdraw {self.amount}\"\n",
    "\n",
    "def withdraw(balance, amount):\n",
    "    if balance < amount:\n",
    "        raise InsufficientFundsError(balance, amount)\n",
    "    return balance - amount\n",
    "\n",
    "try:\n",
    "    balance = 100\n",
    "    amount = 200\n",
    "    balance = withdraw(balance, amount)\n",
    "except InsufficientFundsError as e:\n",
    "    logging.error(\"Insufficient funds{}\".format(e))\n"
   ]
  },
  {
   "cell_type": "markdown",
   "id": "96dbd4bf-db27-4d15-8b7c-777547ab5afc",
   "metadata": {},
   "source": [
    "# Q6. Create custom exception class. Use this class to handle an exception."
   ]
  },
  {
   "cell_type": "code",
   "execution_count": 13,
   "id": "54cf4c6e-424d-4069-b40a-87793506d53f",
   "metadata": {},
   "outputs": [
    {
     "name": "stdout",
     "output_type": "stream",
     "text": [
      "Negative number -5 is not allowed\n"
     ]
    }
   ],
   "source": [
    "class NegativeNumberError(Exception):\n",
    "    def __init__(self, num):\n",
    "        self.num = num\n",
    "        \n",
    "    def __str__(self):\n",
    "        return f\"Negative number {self.num} is not allowed\"\n",
    "\n",
    "def calculate_square(num):\n",
    "    if num < 0:\n",
    "        raise NegativeNumberError(num)\n",
    "    return num ** 2\n",
    "\n",
    "try:\n",
    "    result = calculate_square(-5)\n",
    "except NegativeNumberError as e:\n",
    "    print(e)\n"
   ]
  },
  {
   "cell_type": "code",
   "execution_count": null,
   "id": "261b136e-dba5-4102-82ff-7a6469039970",
   "metadata": {},
   "outputs": [],
   "source": []
  }
 ],
 "metadata": {
  "kernelspec": {
   "display_name": "Python 3 (ipykernel)",
   "language": "python",
   "name": "python3"
  },
  "language_info": {
   "codemirror_mode": {
    "name": "ipython",
    "version": 3
   },
   "file_extension": ".py",
   "mimetype": "text/x-python",
   "name": "python",
   "nbconvert_exporter": "python",
   "pygments_lexer": "ipython3",
   "version": "3.10.8"
  }
 },
 "nbformat": 4,
 "nbformat_minor": 5
}
